2025-08-29 15:56:21,426 INFO    MainThread:2231109 [wandb_setup.py:_flush():67] Current SDK version is 0.19.8
2025-08-29 15:56:21,426 INFO    MainThread:2231109 [wandb_setup.py:_flush():67] Configure stats pid to 2231109
2025-08-29 15:56:21,426 INFO    MainThread:2231109 [wandb_setup.py:_flush():67] Loading settings from /root/.config/wandb/settings
2025-08-29 15:56:21,426 INFO    MainThread:2231109 [wandb_setup.py:_flush():67] Loading settings from /workspace/emotion_KD250628/MKD/CREMA_D_MKD/MKD/wandb/settings
2025-08-29 15:56:21,426 INFO    MainThread:2231109 [wandb_setup.py:_flush():67] Loading settings from environment variables
2025-08-29 15:56:21,426 INFO    MainThread:2231109 [wandb_init.py:setup_run_log_directory():647] Logging user logs to /workspace/emotion_KD250628/MKD/CREMA_D_MKD/MKD/wandb/run-20250829_155621-tm8c1l7a/logs/debug.log
2025-08-29 15:56:21,426 INFO    MainThread:2231109 [wandb_init.py:setup_run_log_directory():648] Logging internal logs to /workspace/emotion_KD250628/MKD/CREMA_D_MKD/MKD/wandb/run-20250829_155621-tm8c1l7a/logs/debug-internal.log
2025-08-29 15:56:21,426 INFO    MainThread:2231109 [wandb_init.py:init():761] calling init triggers
2025-08-29 15:56:21,426 INFO    MainThread:2231109 [wandb_init.py:init():766] wandb.init called with sweep_config: {}
config: {'dataset': 'CREMAD', 'modulation': 'OGM_GE', 'fusion_method': 'sum', 'fps': 1, 'use_video_frames': 3, 'audio_path': '/workspace/datasets/CREMA-D/AudioWAV', 'visual_path': '/workspace/datasets/CREMA-D/', 'batch_size': 64, 'epochs': 200, 'optimizer': 'sgd', 'learning_rate': 0.001, 'lr_decay_step': 70, 'lr_decay_ratio': 0.1, 'modulation_starts': 0, 'modulation_ends': 50, 'alpha': 0.5, 'ckpt_path': '/workspace/emotion_KD250628/MKD/CREMA_D_MKD/MKD/ckpt', 'train': True, 'gpu_ids': '0, 1', 'small_dataset': True, 'unimodal': False, 'unimodal_modality': None, 'random_seed': 8601, '_wandb': {}}
2025-08-29 15:56:21,426 INFO    MainThread:2231109 [wandb_init.py:init():784] starting backend
2025-08-29 15:56:21,426 INFO    MainThread:2231109 [wandb_init.py:init():788] sending inform_init request
2025-08-29 15:56:21,432 INFO    MainThread:2231109 [backend.py:_multiprocessing_setup():101] multiprocessing start_methods=fork,spawn,forkserver, using: spawn
2025-08-29 15:56:21,432 INFO    MainThread:2231109 [wandb_init.py:init():798] backend started and connected
2025-08-29 15:56:21,433 INFO    MainThread:2231109 [wandb_init.py:init():891] updated telemetry
2025-08-29 15:56:21,439 INFO    MainThread:2231109 [wandb_init.py:init():915] communicating run to backend with 90.0 second timeout
2025-08-29 15:56:21,911 INFO    MainThread:2231109 [wandb_init.py:init():990] starting run threads in backend
2025-08-29 15:56:22,146 INFO    MainThread:2231109 [wandb_run.py:_console_start():2375] atexit reg
2025-08-29 15:56:22,146 INFO    MainThread:2231109 [wandb_run.py:_redirect():2227] redirect: wrap_raw
2025-08-29 15:56:22,147 INFO    MainThread:2231109 [wandb_run.py:_redirect():2292] Wrapping output streams.
2025-08-29 15:56:22,147 INFO    MainThread:2231109 [wandb_run.py:_redirect():2315] Redirects installed.
2025-08-29 15:56:22,149 INFO    MainThread:2231109 [wandb_init.py:init():1032] run started, returning control to user process
2025-08-29 15:57:33,154 INFO    MsgRouterThr:2231109 [mailbox.py:close():129] Closing mailbox, abandoning 1 handles.
2025-08-29 15:57:33,384 ERROR   MainThread:2231109 [redirect.py:_on_write():661] error in stderr callback
Traceback (most recent call last):
  File "/opt/conda/lib/python3.10/site-packages/wandb/sdk/lib/redirect.py", line 659, in _on_write
    cb(written_data)
  File "/opt/conda/lib/python3.10/site-packages/wandb/sdk/wandb_run.py", line 2302, in <lambda>
    lambda data: self._console_raw_callback("stderr", data),
  File "/opt/conda/lib/python3.10/site-packages/wandb/sdk/wandb_run.py", line 401, in wrapper_fn
    return func(self, *args, **kwargs)
  File "/opt/conda/lib/python3.10/site-packages/wandb/sdk/wandb_run.py", line 1444, in _console_raw_callback
    self._backend.interface.publish_output_raw(name, data)
  File "/opt/conda/lib/python3.10/site-packages/wandb/sdk/interface/interface.py", line 761, in publish_output_raw
    self._publish_output_raw(o)
  File "/opt/conda/lib/python3.10/site-packages/wandb/sdk/interface/interface_shared.py", line 38, in _publish_output_raw
    self._publish(rec)
  File "/opt/conda/lib/python3.10/site-packages/wandb/sdk/interface/interface_sock.py", line 39, in _publish
    self._sock_client.send_record_publish(record)
  File "/opt/conda/lib/python3.10/site-packages/wandb/sdk/lib/sock_client.py", line 174, in send_record_publish
    self.send_server_request(server_req)
  File "/opt/conda/lib/python3.10/site-packages/wandb/sdk/lib/sock_client.py", line 154, in send_server_request
    self._send_message(msg)
  File "/opt/conda/lib/python3.10/site-packages/wandb/sdk/lib/sock_client.py", line 151, in _send_message
    self._sendall_with_error_handle(header + data)
  File "/opt/conda/lib/python3.10/site-packages/wandb/sdk/lib/sock_client.py", line 130, in _sendall_with_error_handle
    sent = self._sock.send(data)
BrokenPipeError: [Errno 32] Broken pipe
2025-08-29 15:57:33,388 ERROR   MainThread:2231109 [redirect.py:_on_write():661] error in stderr callback
Traceback (most recent call last):
  File "/opt/conda/lib/python3.10/site-packages/wandb/sdk/lib/redirect.py", line 659, in _on_write
    cb(written_data)
  File "/opt/conda/lib/python3.10/site-packages/wandb/sdk/wandb_run.py", line 2302, in <lambda>
    lambda data: self._console_raw_callback("stderr", data),
  File "/opt/conda/lib/python3.10/site-packages/wandb/sdk/wandb_run.py", line 401, in wrapper_fn
    return func(self, *args, **kwargs)
  File "/opt/conda/lib/python3.10/site-packages/wandb/sdk/wandb_run.py", line 1444, in _console_raw_callback
    self._backend.interface.publish_output_raw(name, data)
  File "/opt/conda/lib/python3.10/site-packages/wandb/sdk/interface/interface.py", line 761, in publish_output_raw
    self._publish_output_raw(o)
  File "/opt/conda/lib/python3.10/site-packages/wandb/sdk/interface/interface_shared.py", line 38, in _publish_output_raw
    self._publish(rec)
  File "/opt/conda/lib/python3.10/site-packages/wandb/sdk/interface/interface_sock.py", line 39, in _publish
    self._sock_client.send_record_publish(record)
  File "/opt/conda/lib/python3.10/site-packages/wandb/sdk/lib/sock_client.py", line 174, in send_record_publish
    self.send_server_request(server_req)
  File "/opt/conda/lib/python3.10/site-packages/wandb/sdk/lib/sock_client.py", line 154, in send_server_request
    self._send_message(msg)
  File "/opt/conda/lib/python3.10/site-packages/wandb/sdk/lib/sock_client.py", line 151, in _send_message
    self._sendall_with_error_handle(header + data)
  File "/opt/conda/lib/python3.10/site-packages/wandb/sdk/lib/sock_client.py", line 130, in _sendall_with_error_handle
    sent = self._sock.send(data)
BrokenPipeError: [Errno 32] Broken pipe
2025-08-29 15:57:33,388 ERROR   MainThread:2231109 [redirect.py:_on_write():661] error in stderr callback
Traceback (most recent call last):
  File "/opt/conda/lib/python3.10/site-packages/wandb/sdk/lib/redirect.py", line 659, in _on_write
    cb(written_data)
  File "/opt/conda/lib/python3.10/site-packages/wandb/sdk/wandb_run.py", line 2302, in <lambda>
    lambda data: self._console_raw_callback("stderr", data),
  File "/opt/conda/lib/python3.10/site-packages/wandb/sdk/wandb_run.py", line 401, in wrapper_fn
    return func(self, *args, **kwargs)
  File "/opt/conda/lib/python3.10/site-packages/wandb/sdk/wandb_run.py", line 1444, in _console_raw_callback
    self._backend.interface.publish_output_raw(name, data)
  File "/opt/conda/lib/python3.10/site-packages/wandb/sdk/interface/interface.py", line 761, in publish_output_raw
    self._publish_output_raw(o)
  File "/opt/conda/lib/python3.10/site-packages/wandb/sdk/interface/interface_shared.py", line 38, in _publish_output_raw
    self._publish(rec)
  File "/opt/conda/lib/python3.10/site-packages/wandb/sdk/interface/interface_sock.py", line 39, in _publish
    self._sock_client.send_record_publish(record)
  File "/opt/conda/lib/python3.10/site-packages/wandb/sdk/lib/sock_client.py", line 174, in send_record_publish
    self.send_server_request(server_req)
  File "/opt/conda/lib/python3.10/site-packages/wandb/sdk/lib/sock_client.py", line 154, in send_server_request
    self._send_message(msg)
  File "/opt/conda/lib/python3.10/site-packages/wandb/sdk/lib/sock_client.py", line 151, in _send_message
    self._sendall_with_error_handle(header + data)
  File "/opt/conda/lib/python3.10/site-packages/wandb/sdk/lib/sock_client.py", line 130, in _sendall_with_error_handle
    sent = self._sock.send(data)
BrokenPipeError: [Errno 32] Broken pipe
2025-08-29 15:57:33,389 ERROR   MainThread:2231109 [redirect.py:_on_write():661] error in stderr callback
Traceback (most recent call last):
  File "/opt/conda/lib/python3.10/site-packages/wandb/sdk/lib/redirect.py", line 659, in _on_write
    cb(written_data)
  File "/opt/conda/lib/python3.10/site-packages/wandb/sdk/wandb_run.py", line 2302, in <lambda>
    lambda data: self._console_raw_callback("stderr", data),
  File "/opt/conda/lib/python3.10/site-packages/wandb/sdk/wandb_run.py", line 401, in wrapper_fn
    return func(self, *args, **kwargs)
  File "/opt/conda/lib/python3.10/site-packages/wandb/sdk/wandb_run.py", line 1444, in _console_raw_callback
    self._backend.interface.publish_output_raw(name, data)
  File "/opt/conda/lib/python3.10/site-packages/wandb/sdk/interface/interface.py", line 761, in publish_output_raw
    self._publish_output_raw(o)
  File "/opt/conda/lib/python3.10/site-packages/wandb/sdk/interface/interface_shared.py", line 38, in _publish_output_raw
    self._publish(rec)
  File "/opt/conda/lib/python3.10/site-packages/wandb/sdk/interface/interface_sock.py", line 39, in _publish
    self._sock_client.send_record_publish(record)
  File "/opt/conda/lib/python3.10/site-packages/wandb/sdk/lib/sock_client.py", line 174, in send_record_publish
    self.send_server_request(server_req)
  File "/opt/conda/lib/python3.10/site-packages/wandb/sdk/lib/sock_client.py", line 154, in send_server_request
    self._send_message(msg)
  File "/opt/conda/lib/python3.10/site-packages/wandb/sdk/lib/sock_client.py", line 151, in _send_message
    self._sendall_with_error_handle(header + data)
  File "/opt/conda/lib/python3.10/site-packages/wandb/sdk/lib/sock_client.py", line 130, in _sendall_with_error_handle
    sent = self._sock.send(data)
BrokenPipeError: [Errno 32] Broken pipe
2025-08-29 15:57:33,389 ERROR   MainThread:2231109 [redirect.py:_on_write():661] error in stderr callback
Traceback (most recent call last):
  File "/opt/conda/lib/python3.10/site-packages/wandb/sdk/lib/redirect.py", line 659, in _on_write
    cb(written_data)
  File "/opt/conda/lib/python3.10/site-packages/wandb/sdk/wandb_run.py", line 2302, in <lambda>
    lambda data: self._console_raw_callback("stderr", data),
  File "/opt/conda/lib/python3.10/site-packages/wandb/sdk/wandb_run.py", line 401, in wrapper_fn
    return func(self, *args, **kwargs)
  File "/opt/conda/lib/python3.10/site-packages/wandb/sdk/wandb_run.py", line 1444, in _console_raw_callback
    self._backend.interface.publish_output_raw(name, data)
  File "/opt/conda/lib/python3.10/site-packages/wandb/sdk/interface/interface.py", line 761, in publish_output_raw
    self._publish_output_raw(o)
  File "/opt/conda/lib/python3.10/site-packages/wandb/sdk/interface/interface_shared.py", line 38, in _publish_output_raw
    self._publish(rec)
  File "/opt/conda/lib/python3.10/site-packages/wandb/sdk/interface/interface_sock.py", line 39, in _publish
    self._sock_client.send_record_publish(record)
  File "/opt/conda/lib/python3.10/site-packages/wandb/sdk/lib/sock_client.py", line 174, in send_record_publish
    self.send_server_request(server_req)
  File "/opt/conda/lib/python3.10/site-packages/wandb/sdk/lib/sock_client.py", line 154, in send_server_request
    self._send_message(msg)
  File "/opt/conda/lib/python3.10/site-packages/wandb/sdk/lib/sock_client.py", line 151, in _send_message
    self._sendall_with_error_handle(header + data)
  File "/opt/conda/lib/python3.10/site-packages/wandb/sdk/lib/sock_client.py", line 130, in _sendall_with_error_handle
    sent = self._sock.send(data)
BrokenPipeError: [Errno 32] Broken pipe
2025-08-29 15:57:33,390 ERROR   MainThread:2231109 [redirect.py:_on_write():661] error in stderr callback
Traceback (most recent call last):
  File "/opt/conda/lib/python3.10/site-packages/wandb/sdk/lib/redirect.py", line 659, in _on_write
    cb(written_data)
  File "/opt/conda/lib/python3.10/site-packages/wandb/sdk/wandb_run.py", line 2302, in <lambda>
    lambda data: self._console_raw_callback("stderr", data),
  File "/opt/conda/lib/python3.10/site-packages/wandb/sdk/wandb_run.py", line 401, in wrapper_fn
    return func(self, *args, **kwargs)
  File "/opt/conda/lib/python3.10/site-packages/wandb/sdk/wandb_run.py", line 1444, in _console_raw_callback
    self._backend.interface.publish_output_raw(name, data)
  File "/opt/conda/lib/python3.10/site-packages/wandb/sdk/interface/interface.py", line 761, in publish_output_raw
    self._publish_output_raw(o)
  File "/opt/conda/lib/python3.10/site-packages/wandb/sdk/interface/interface_shared.py", line 38, in _publish_output_raw
    self._publish(rec)
  File "/opt/conda/lib/python3.10/site-packages/wandb/sdk/interface/interface_sock.py", line 39, in _publish
    self._sock_client.send_record_publish(record)
  File "/opt/conda/lib/python3.10/site-packages/wandb/sdk/lib/sock_client.py", line 174, in send_record_publish
    self.send_server_request(server_req)
  File "/opt/conda/lib/python3.10/site-packages/wandb/sdk/lib/sock_client.py", line 154, in send_server_request
    self._send_message(msg)
  File "/opt/conda/lib/python3.10/site-packages/wandb/sdk/lib/sock_client.py", line 151, in _send_message
    self._sendall_with_error_handle(header + data)
  File "/opt/conda/lib/python3.10/site-packages/wandb/sdk/lib/sock_client.py", line 130, in _sendall_with_error_handle
    sent = self._sock.send(data)
BrokenPipeError: [Errno 32] Broken pipe
2025-08-29 15:57:33,391 ERROR   MainThread:2231109 [redirect.py:_on_write():661] error in stderr callback
Traceback (most recent call last):
  File "/opt/conda/lib/python3.10/site-packages/wandb/sdk/lib/redirect.py", line 659, in _on_write
    cb(written_data)
  File "/opt/conda/lib/python3.10/site-packages/wandb/sdk/wandb_run.py", line 2302, in <lambda>
    lambda data: self._console_raw_callback("stderr", data),
  File "/opt/conda/lib/python3.10/site-packages/wandb/sdk/wandb_run.py", line 401, in wrapper_fn
    return func(self, *args, **kwargs)
  File "/opt/conda/lib/python3.10/site-packages/wandb/sdk/wandb_run.py", line 1444, in _console_raw_callback
    self._backend.interface.publish_output_raw(name, data)
  File "/opt/conda/lib/python3.10/site-packages/wandb/sdk/interface/interface.py", line 761, in publish_output_raw
    self._publish_output_raw(o)
  File "/opt/conda/lib/python3.10/site-packages/wandb/sdk/interface/interface_shared.py", line 38, in _publish_output_raw
    self._publish(rec)
  File "/opt/conda/lib/python3.10/site-packages/wandb/sdk/interface/interface_sock.py", line 39, in _publish
    self._sock_client.send_record_publish(record)
  File "/opt/conda/lib/python3.10/site-packages/wandb/sdk/lib/sock_client.py", line 174, in send_record_publish
    self.send_server_request(server_req)
  File "/opt/conda/lib/python3.10/site-packages/wandb/sdk/lib/sock_client.py", line 154, in send_server_request
    self._send_message(msg)
  File "/opt/conda/lib/python3.10/site-packages/wandb/sdk/lib/sock_client.py", line 151, in _send_message
    self._sendall_with_error_handle(header + data)
  File "/opt/conda/lib/python3.10/site-packages/wandb/sdk/lib/sock_client.py", line 130, in _sendall_with_error_handle
    sent = self._sock.send(data)
BrokenPipeError: [Errno 32] Broken pipe
2025-08-29 15:57:33,391 ERROR   MainThread:2231109 [redirect.py:_on_write():661] error in stderr callback
Traceback (most recent call last):
  File "/opt/conda/lib/python3.10/site-packages/wandb/sdk/lib/redirect.py", line 659, in _on_write
    cb(written_data)
  File "/opt/conda/lib/python3.10/site-packages/wandb/sdk/wandb_run.py", line 2302, in <lambda>
    lambda data: self._console_raw_callback("stderr", data),
  File "/opt/conda/lib/python3.10/site-packages/wandb/sdk/wandb_run.py", line 401, in wrapper_fn
    return func(self, *args, **kwargs)
  File "/opt/conda/lib/python3.10/site-packages/wandb/sdk/wandb_run.py", line 1444, in _console_raw_callback
    self._backend.interface.publish_output_raw(name, data)
  File "/opt/conda/lib/python3.10/site-packages/wandb/sdk/interface/interface.py", line 761, in publish_output_raw
    self._publish_output_raw(o)
  File "/opt/conda/lib/python3.10/site-packages/wandb/sdk/interface/interface_shared.py", line 38, in _publish_output_raw
    self._publish(rec)
  File "/opt/conda/lib/python3.10/site-packages/wandb/sdk/interface/interface_sock.py", line 39, in _publish
    self._sock_client.send_record_publish(record)
  File "/opt/conda/lib/python3.10/site-packages/wandb/sdk/lib/sock_client.py", line 174, in send_record_publish
    self.send_server_request(server_req)
  File "/opt/conda/lib/python3.10/site-packages/wandb/sdk/lib/sock_client.py", line 154, in send_server_request
    self._send_message(msg)
  File "/opt/conda/lib/python3.10/site-packages/wandb/sdk/lib/sock_client.py", line 151, in _send_message
    self._sendall_with_error_handle(header + data)
  File "/opt/conda/lib/python3.10/site-packages/wandb/sdk/lib/sock_client.py", line 130, in _sendall_with_error_handle
    sent = self._sock.send(data)
BrokenPipeError: [Errno 32] Broken pipe
2025-08-29 15:57:33,392 ERROR   MainThread:2231109 [redirect.py:_on_write():661] error in stderr callback
Traceback (most recent call last):
  File "/opt/conda/lib/python3.10/site-packages/wandb/sdk/lib/redirect.py", line 659, in _on_write
    cb(written_data)
  File "/opt/conda/lib/python3.10/site-packages/wandb/sdk/wandb_run.py", line 2302, in <lambda>
    lambda data: self._console_raw_callback("stderr", data),
  File "/opt/conda/lib/python3.10/site-packages/wandb/sdk/wandb_run.py", line 401, in wrapper_fn
    return func(self, *args, **kwargs)
  File "/opt/conda/lib/python3.10/site-packages/wandb/sdk/wandb_run.py", line 1444, in _console_raw_callback
    self._backend.interface.publish_output_raw(name, data)
  File "/opt/conda/lib/python3.10/site-packages/wandb/sdk/interface/interface.py", line 761, in publish_output_raw
    self._publish_output_raw(o)
  File "/opt/conda/lib/python3.10/site-packages/wandb/sdk/interface/interface_shared.py", line 38, in _publish_output_raw
    self._publish(rec)
  File "/opt/conda/lib/python3.10/site-packages/wandb/sdk/interface/interface_sock.py", line 39, in _publish
    self._sock_client.send_record_publish(record)
  File "/opt/conda/lib/python3.10/site-packages/wandb/sdk/lib/sock_client.py", line 174, in send_record_publish
    self.send_server_request(server_req)
  File "/opt/conda/lib/python3.10/site-packages/wandb/sdk/lib/sock_client.py", line 154, in send_server_request
    self._send_message(msg)
  File "/opt/conda/lib/python3.10/site-packages/wandb/sdk/lib/sock_client.py", line 151, in _send_message
    self._sendall_with_error_handle(header + data)
  File "/opt/conda/lib/python3.10/site-packages/wandb/sdk/lib/sock_client.py", line 130, in _sendall_with_error_handle
    sent = self._sock.send(data)
BrokenPipeError: [Errno 32] Broken pipe
2025-08-29 15:57:33,392 ERROR   MainThread:2231109 [redirect.py:_on_write():661] error in stderr callback
Traceback (most recent call last):
  File "/opt/conda/lib/python3.10/site-packages/wandb/sdk/lib/redirect.py", line 659, in _on_write
    cb(written_data)
  File "/opt/conda/lib/python3.10/site-packages/wandb/sdk/wandb_run.py", line 2302, in <lambda>
    lambda data: self._console_raw_callback("stderr", data),
  File "/opt/conda/lib/python3.10/site-packages/wandb/sdk/wandb_run.py", line 401, in wrapper_fn
    return func(self, *args, **kwargs)
  File "/opt/conda/lib/python3.10/site-packages/wandb/sdk/wandb_run.py", line 1444, in _console_raw_callback
    self._backend.interface.publish_output_raw(name, data)
  File "/opt/conda/lib/python3.10/site-packages/wandb/sdk/interface/interface.py", line 761, in publish_output_raw
    self._publish_output_raw(o)
  File "/opt/conda/lib/python3.10/site-packages/wandb/sdk/interface/interface_shared.py", line 38, in _publish_output_raw
    self._publish(rec)
  File "/opt/conda/lib/python3.10/site-packages/wandb/sdk/interface/interface_sock.py", line 39, in _publish
    self._sock_client.send_record_publish(record)
  File "/opt/conda/lib/python3.10/site-packages/wandb/sdk/lib/sock_client.py", line 174, in send_record_publish
    self.send_server_request(server_req)
  File "/opt/conda/lib/python3.10/site-packages/wandb/sdk/lib/sock_client.py", line 154, in send_server_request
    self._send_message(msg)
  File "/opt/conda/lib/python3.10/site-packages/wandb/sdk/lib/sock_client.py", line 151, in _send_message
    self._sendall_with_error_handle(header + data)
  File "/opt/conda/lib/python3.10/site-packages/wandb/sdk/lib/sock_client.py", line 130, in _sendall_with_error_handle
    sent = self._sock.send(data)
BrokenPipeError: [Errno 32] Broken pipe
2025-08-29 15:57:33,393 ERROR   MainThread:2231109 [redirect.py:_on_write():661] error in stderr callback
Traceback (most recent call last):
  File "/opt/conda/lib/python3.10/site-packages/wandb/sdk/lib/redirect.py", line 659, in _on_write
    cb(written_data)
  File "/opt/conda/lib/python3.10/site-packages/wandb/sdk/wandb_run.py", line 2302, in <lambda>
    lambda data: self._console_raw_callback("stderr", data),
  File "/opt/conda/lib/python3.10/site-packages/wandb/sdk/wandb_run.py", line 401, in wrapper_fn
    return func(self, *args, **kwargs)
  File "/opt/conda/lib/python3.10/site-packages/wandb/sdk/wandb_run.py", line 1444, in _console_raw_callback
    self._backend.interface.publish_output_raw(name, data)
  File "/opt/conda/lib/python3.10/site-packages/wandb/sdk/interface/interface.py", line 761, in publish_output_raw
    self._publish_output_raw(o)
  File "/opt/conda/lib/python3.10/site-packages/wandb/sdk/interface/interface_shared.py", line 38, in _publish_output_raw
    self._publish(rec)
  File "/opt/conda/lib/python3.10/site-packages/wandb/sdk/interface/interface_sock.py", line 39, in _publish
    self._sock_client.send_record_publish(record)
  File "/opt/conda/lib/python3.10/site-packages/wandb/sdk/lib/sock_client.py", line 174, in send_record_publish
    self.send_server_request(server_req)
  File "/opt/conda/lib/python3.10/site-packages/wandb/sdk/lib/sock_client.py", line 154, in send_server_request
    self._send_message(msg)
  File "/opt/conda/lib/python3.10/site-packages/wandb/sdk/lib/sock_client.py", line 151, in _send_message
    self._sendall_with_error_handle(header + data)
  File "/opt/conda/lib/python3.10/site-packages/wandb/sdk/lib/sock_client.py", line 130, in _sendall_with_error_handle
    sent = self._sock.send(data)
BrokenPipeError: [Errno 32] Broken pipe
2025-08-29 15:57:33,393 ERROR   MainThread:2231109 [redirect.py:_on_write():661] error in stderr callback
Traceback (most recent call last):
  File "/opt/conda/lib/python3.10/site-packages/wandb/sdk/lib/redirect.py", line 659, in _on_write
    cb(written_data)
  File "/opt/conda/lib/python3.10/site-packages/wandb/sdk/wandb_run.py", line 2302, in <lambda>
    lambda data: self._console_raw_callback("stderr", data),
  File "/opt/conda/lib/python3.10/site-packages/wandb/sdk/wandb_run.py", line 401, in wrapper_fn
    return func(self, *args, **kwargs)
  File "/opt/conda/lib/python3.10/site-packages/wandb/sdk/wandb_run.py", line 1444, in _console_raw_callback
    self._backend.interface.publish_output_raw(name, data)
  File "/opt/conda/lib/python3.10/site-packages/wandb/sdk/interface/interface.py", line 761, in publish_output_raw
    self._publish_output_raw(o)
  File "/opt/conda/lib/python3.10/site-packages/wandb/sdk/interface/interface_shared.py", line 38, in _publish_output_raw
    self._publish(rec)
  File "/opt/conda/lib/python3.10/site-packages/wandb/sdk/interface/interface_sock.py", line 39, in _publish
    self._sock_client.send_record_publish(record)
  File "/opt/conda/lib/python3.10/site-packages/wandb/sdk/lib/sock_client.py", line 174, in send_record_publish
    self.send_server_request(server_req)
  File "/opt/conda/lib/python3.10/site-packages/wandb/sdk/lib/sock_client.py", line 154, in send_server_request
    self._send_message(msg)
  File "/opt/conda/lib/python3.10/site-packages/wandb/sdk/lib/sock_client.py", line 151, in _send_message
    self._sendall_with_error_handle(header + data)
  File "/opt/conda/lib/python3.10/site-packages/wandb/sdk/lib/sock_client.py", line 130, in _sendall_with_error_handle
    sent = self._sock.send(data)
BrokenPipeError: [Errno 32] Broken pipe
2025-08-29 15:57:33,394 ERROR   MainThread:2231109 [redirect.py:_on_write():661] error in stderr callback
Traceback (most recent call last):
  File "/opt/conda/lib/python3.10/site-packages/wandb/sdk/lib/redirect.py", line 659, in _on_write
    cb(written_data)
  File "/opt/conda/lib/python3.10/site-packages/wandb/sdk/wandb_run.py", line 2302, in <lambda>
    lambda data: self._console_raw_callback("stderr", data),
  File "/opt/conda/lib/python3.10/site-packages/wandb/sdk/wandb_run.py", line 401, in wrapper_fn
    return func(self, *args, **kwargs)
  File "/opt/conda/lib/python3.10/site-packages/wandb/sdk/wandb_run.py", line 1444, in _console_raw_callback
    self._backend.interface.publish_output_raw(name, data)
  File "/opt/conda/lib/python3.10/site-packages/wandb/sdk/interface/interface.py", line 761, in publish_output_raw
    self._publish_output_raw(o)
  File "/opt/conda/lib/python3.10/site-packages/wandb/sdk/interface/interface_shared.py", line 38, in _publish_output_raw
    self._publish(rec)
  File "/opt/conda/lib/python3.10/site-packages/wandb/sdk/interface/interface_sock.py", line 39, in _publish
    self._sock_client.send_record_publish(record)
  File "/opt/conda/lib/python3.10/site-packages/wandb/sdk/lib/sock_client.py", line 174, in send_record_publish
    self.send_server_request(server_req)
  File "/opt/conda/lib/python3.10/site-packages/wandb/sdk/lib/sock_client.py", line 154, in send_server_request
    self._send_message(msg)
  File "/opt/conda/lib/python3.10/site-packages/wandb/sdk/lib/sock_client.py", line 151, in _send_message
    self._sendall_with_error_handle(header + data)
  File "/opt/conda/lib/python3.10/site-packages/wandb/sdk/lib/sock_client.py", line 130, in _sendall_with_error_handle
    sent = self._sock.send(data)
BrokenPipeError: [Errno 32] Broken pipe
2025-08-29 15:57:33,395 ERROR   MainThread:2231109 [redirect.py:_on_write():661] error in stderr callback
Traceback (most recent call last):
  File "/opt/conda/lib/python3.10/site-packages/wandb/sdk/lib/redirect.py", line 659, in _on_write
    cb(written_data)
  File "/opt/conda/lib/python3.10/site-packages/wandb/sdk/wandb_run.py", line 2302, in <lambda>
    lambda data: self._console_raw_callback("stderr", data),
  File "/opt/conda/lib/python3.10/site-packages/wandb/sdk/wandb_run.py", line 401, in wrapper_fn
    return func(self, *args, **kwargs)
  File "/opt/conda/lib/python3.10/site-packages/wandb/sdk/wandb_run.py", line 1444, in _console_raw_callback
    self._backend.interface.publish_output_raw(name, data)
  File "/opt/conda/lib/python3.10/site-packages/wandb/sdk/interface/interface.py", line 761, in publish_output_raw
    self._publish_output_raw(o)
  File "/opt/conda/lib/python3.10/site-packages/wandb/sdk/interface/interface_shared.py", line 38, in _publish_output_raw
    self._publish(rec)
  File "/opt/conda/lib/python3.10/site-packages/wandb/sdk/interface/interface_sock.py", line 39, in _publish
    self._sock_client.send_record_publish(record)
  File "/opt/conda/lib/python3.10/site-packages/wandb/sdk/lib/sock_client.py", line 174, in send_record_publish
    self.send_server_request(server_req)
  File "/opt/conda/lib/python3.10/site-packages/wandb/sdk/lib/sock_client.py", line 154, in send_server_request
    self._send_message(msg)
  File "/opt/conda/lib/python3.10/site-packages/wandb/sdk/lib/sock_client.py", line 151, in _send_message
    self._sendall_with_error_handle(header + data)
  File "/opt/conda/lib/python3.10/site-packages/wandb/sdk/lib/sock_client.py", line 130, in _sendall_with_error_handle
    sent = self._sock.send(data)
BrokenPipeError: [Errno 32] Broken pipe
2025-08-29 15:57:33,396 ERROR   MainThread:2231109 [redirect.py:_on_write():661] error in stderr callback
Traceback (most recent call last):
  File "/opt/conda/lib/python3.10/site-packages/wandb/sdk/lib/redirect.py", line 659, in _on_write
    cb(written_data)
  File "/opt/conda/lib/python3.10/site-packages/wandb/sdk/wandb_run.py", line 2302, in <lambda>
    lambda data: self._console_raw_callback("stderr", data),
  File "/opt/conda/lib/python3.10/site-packages/wandb/sdk/wandb_run.py", line 401, in wrapper_fn
    return func(self, *args, **kwargs)
  File "/opt/conda/lib/python3.10/site-packages/wandb/sdk/wandb_run.py", line 1444, in _console_raw_callback
    self._backend.interface.publish_output_raw(name, data)
  File "/opt/conda/lib/python3.10/site-packages/wandb/sdk/interface/interface.py", line 761, in publish_output_raw
    self._publish_output_raw(o)
  File "/opt/conda/lib/python3.10/site-packages/wandb/sdk/interface/interface_shared.py", line 38, in _publish_output_raw
    self._publish(rec)
  File "/opt/conda/lib/python3.10/site-packages/wandb/sdk/interface/interface_sock.py", line 39, in _publish
    self._sock_client.send_record_publish(record)
  File "/opt/conda/lib/python3.10/site-packages/wandb/sdk/lib/sock_client.py", line 174, in send_record_publish
    self.send_server_request(server_req)
  File "/opt/conda/lib/python3.10/site-packages/wandb/sdk/lib/sock_client.py", line 154, in send_server_request
    self._send_message(msg)
  File "/opt/conda/lib/python3.10/site-packages/wandb/sdk/lib/sock_client.py", line 151, in _send_message
    self._sendall_with_error_handle(header + data)
  File "/opt/conda/lib/python3.10/site-packages/wandb/sdk/lib/sock_client.py", line 130, in _sendall_with_error_handle
    sent = self._sock.send(data)
BrokenPipeError: [Errno 32] Broken pipe
2025-08-29 15:57:33,398 ERROR   MainThread:2231109 [redirect.py:_on_write():661] error in stderr callback
Traceback (most recent call last):
  File "/opt/conda/lib/python3.10/site-packages/wandb/sdk/lib/redirect.py", line 659, in _on_write
    cb(written_data)
  File "/opt/conda/lib/python3.10/site-packages/wandb/sdk/wandb_run.py", line 2302, in <lambda>
    lambda data: self._console_raw_callback("stderr", data),
  File "/opt/conda/lib/python3.10/site-packages/wandb/sdk/wandb_run.py", line 401, in wrapper_fn
    return func(self, *args, **kwargs)
  File "/opt/conda/lib/python3.10/site-packages/wandb/sdk/wandb_run.py", line 1444, in _console_raw_callback
    self._backend.interface.publish_output_raw(name, data)
  File "/opt/conda/lib/python3.10/site-packages/wandb/sdk/interface/interface.py", line 761, in publish_output_raw
    self._publish_output_raw(o)
  File "/opt/conda/lib/python3.10/site-packages/wandb/sdk/interface/interface_shared.py", line 38, in _publish_output_raw
    self._publish(rec)
  File "/opt/conda/lib/python3.10/site-packages/wandb/sdk/interface/interface_sock.py", line 39, in _publish
    self._sock_client.send_record_publish(record)
  File "/opt/conda/lib/python3.10/site-packages/wandb/sdk/lib/sock_client.py", line 174, in send_record_publish
    self.send_server_request(server_req)
  File "/opt/conda/lib/python3.10/site-packages/wandb/sdk/lib/sock_client.py", line 154, in send_server_request
    self._send_message(msg)
  File "/opt/conda/lib/python3.10/site-packages/wandb/sdk/lib/sock_client.py", line 151, in _send_message
    self._sendall_with_error_handle(header + data)
  File "/opt/conda/lib/python3.10/site-packages/wandb/sdk/lib/sock_client.py", line 130, in _sendall_with_error_handle
    sent = self._sock.send(data)
BrokenPipeError: [Errno 32] Broken pipe
2025-08-29 15:57:33,399 ERROR   MainThread:2231109 [redirect.py:_on_write():661] error in stderr callback
Traceback (most recent call last):
  File "/opt/conda/lib/python3.10/site-packages/wandb/sdk/lib/redirect.py", line 659, in _on_write
    cb(written_data)
  File "/opt/conda/lib/python3.10/site-packages/wandb/sdk/wandb_run.py", line 2302, in <lambda>
    lambda data: self._console_raw_callback("stderr", data),
  File "/opt/conda/lib/python3.10/site-packages/wandb/sdk/wandb_run.py", line 401, in wrapper_fn
    return func(self, *args, **kwargs)
  File "/opt/conda/lib/python3.10/site-packages/wandb/sdk/wandb_run.py", line 1444, in _console_raw_callback
    self._backend.interface.publish_output_raw(name, data)
  File "/opt/conda/lib/python3.10/site-packages/wandb/sdk/interface/interface.py", line 761, in publish_output_raw
    self._publish_output_raw(o)
  File "/opt/conda/lib/python3.10/site-packages/wandb/sdk/interface/interface_shared.py", line 38, in _publish_output_raw
    self._publish(rec)
  File "/opt/conda/lib/python3.10/site-packages/wandb/sdk/interface/interface_sock.py", line 39, in _publish
    self._sock_client.send_record_publish(record)
  File "/opt/conda/lib/python3.10/site-packages/wandb/sdk/lib/sock_client.py", line 174, in send_record_publish
    self.send_server_request(server_req)
  File "/opt/conda/lib/python3.10/site-packages/wandb/sdk/lib/sock_client.py", line 154, in send_server_request
    self._send_message(msg)
  File "/opt/conda/lib/python3.10/site-packages/wandb/sdk/lib/sock_client.py", line 151, in _send_message
    self._sendall_with_error_handle(header + data)
  File "/opt/conda/lib/python3.10/site-packages/wandb/sdk/lib/sock_client.py", line 130, in _sendall_with_error_handle
    sent = self._sock.send(data)
BrokenPipeError: [Errno 32] Broken pipe
2025-08-29 15:57:33,401 ERROR   MainThread:2231109 [redirect.py:_on_write():661] error in stderr callback
Traceback (most recent call last):
  File "/opt/conda/lib/python3.10/site-packages/wandb/sdk/lib/redirect.py", line 659, in _on_write
    cb(written_data)
  File "/opt/conda/lib/python3.10/site-packages/wandb/sdk/wandb_run.py", line 2302, in <lambda>
    lambda data: self._console_raw_callback("stderr", data),
  File "/opt/conda/lib/python3.10/site-packages/wandb/sdk/wandb_run.py", line 401, in wrapper_fn
    return func(self, *args, **kwargs)
  File "/opt/conda/lib/python3.10/site-packages/wandb/sdk/wandb_run.py", line 1444, in _console_raw_callback
    self._backend.interface.publish_output_raw(name, data)
  File "/opt/conda/lib/python3.10/site-packages/wandb/sdk/interface/interface.py", line 761, in publish_output_raw
    self._publish_output_raw(o)
  File "/opt/conda/lib/python3.10/site-packages/wandb/sdk/interface/interface_shared.py", line 38, in _publish_output_raw
    self._publish(rec)
  File "/opt/conda/lib/python3.10/site-packages/wandb/sdk/interface/interface_sock.py", line 39, in _publish
    self._sock_client.send_record_publish(record)
  File "/opt/conda/lib/python3.10/site-packages/wandb/sdk/lib/sock_client.py", line 174, in send_record_publish
    self.send_server_request(server_req)
  File "/opt/conda/lib/python3.10/site-packages/wandb/sdk/lib/sock_client.py", line 154, in send_server_request
    self._send_message(msg)
  File "/opt/conda/lib/python3.10/site-packages/wandb/sdk/lib/sock_client.py", line 151, in _send_message
    self._sendall_with_error_handle(header + data)
  File "/opt/conda/lib/python3.10/site-packages/wandb/sdk/lib/sock_client.py", line 130, in _sendall_with_error_handle
    sent = self._sock.send(data)
BrokenPipeError: [Errno 32] Broken pipe
2025-08-29 15:57:33,401 ERROR   MainThread:2231109 [redirect.py:_on_write():661] error in stderr callback
Traceback (most recent call last):
  File "/opt/conda/lib/python3.10/site-packages/wandb/sdk/lib/redirect.py", line 659, in _on_write
    cb(written_data)
  File "/opt/conda/lib/python3.10/site-packages/wandb/sdk/wandb_run.py", line 2302, in <lambda>
    lambda data: self._console_raw_callback("stderr", data),
  File "/opt/conda/lib/python3.10/site-packages/wandb/sdk/wandb_run.py", line 401, in wrapper_fn
    return func(self, *args, **kwargs)
  File "/opt/conda/lib/python3.10/site-packages/wandb/sdk/wandb_run.py", line 1444, in _console_raw_callback
    self._backend.interface.publish_output_raw(name, data)
  File "/opt/conda/lib/python3.10/site-packages/wandb/sdk/interface/interface.py", line 761, in publish_output_raw
    self._publish_output_raw(o)
  File "/opt/conda/lib/python3.10/site-packages/wandb/sdk/interface/interface_shared.py", line 38, in _publish_output_raw
    self._publish(rec)
  File "/opt/conda/lib/python3.10/site-packages/wandb/sdk/interface/interface_sock.py", line 39, in _publish
    self._sock_client.send_record_publish(record)
  File "/opt/conda/lib/python3.10/site-packages/wandb/sdk/lib/sock_client.py", line 174, in send_record_publish
    self.send_server_request(server_req)
  File "/opt/conda/lib/python3.10/site-packages/wandb/sdk/lib/sock_client.py", line 154, in send_server_request
    self._send_message(msg)
  File "/opt/conda/lib/python3.10/site-packages/wandb/sdk/lib/sock_client.py", line 151, in _send_message
    self._sendall_with_error_handle(header + data)
  File "/opt/conda/lib/python3.10/site-packages/wandb/sdk/lib/sock_client.py", line 130, in _sendall_with_error_handle
    sent = self._sock.send(data)
BrokenPipeError: [Errno 32] Broken pipe
2025-08-29 15:57:33,401 ERROR   MainThread:2231109 [redirect.py:_on_write():661] error in stderr callback
Traceback (most recent call last):
  File "/opt/conda/lib/python3.10/site-packages/wandb/sdk/lib/redirect.py", line 659, in _on_write
    cb(written_data)
  File "/opt/conda/lib/python3.10/site-packages/wandb/sdk/wandb_run.py", line 2302, in <lambda>
    lambda data: self._console_raw_callback("stderr", data),
  File "/opt/conda/lib/python3.10/site-packages/wandb/sdk/wandb_run.py", line 401, in wrapper_fn
    return func(self, *args, **kwargs)
  File "/opt/conda/lib/python3.10/site-packages/wandb/sdk/wandb_run.py", line 1444, in _console_raw_callback
    self._backend.interface.publish_output_raw(name, data)
  File "/opt/conda/lib/python3.10/site-packages/wandb/sdk/interface/interface.py", line 761, in publish_output_raw
    self._publish_output_raw(o)
  File "/opt/conda/lib/python3.10/site-packages/wandb/sdk/interface/interface_shared.py", line 38, in _publish_output_raw
    self._publish(rec)
  File "/opt/conda/lib/python3.10/site-packages/wandb/sdk/interface/interface_sock.py", line 39, in _publish
    self._sock_client.send_record_publish(record)
  File "/opt/conda/lib/python3.10/site-packages/wandb/sdk/lib/sock_client.py", line 174, in send_record_publish
    self.send_server_request(server_req)
  File "/opt/conda/lib/python3.10/site-packages/wandb/sdk/lib/sock_client.py", line 154, in send_server_request
    self._send_message(msg)
  File "/opt/conda/lib/python3.10/site-packages/wandb/sdk/lib/sock_client.py", line 151, in _send_message
    self._sendall_with_error_handle(header + data)
  File "/opt/conda/lib/python3.10/site-packages/wandb/sdk/lib/sock_client.py", line 130, in _sendall_with_error_handle
    sent = self._sock.send(data)
BrokenPipeError: [Errno 32] Broken pipe
2025-08-29 15:57:33,402 ERROR   MainThread:2231109 [redirect.py:_on_write():661] error in stderr callback
Traceback (most recent call last):
  File "/opt/conda/lib/python3.10/site-packages/wandb/sdk/lib/redirect.py", line 659, in _on_write
    cb(written_data)
  File "/opt/conda/lib/python3.10/site-packages/wandb/sdk/wandb_run.py", line 2302, in <lambda>
    lambda data: self._console_raw_callback("stderr", data),
  File "/opt/conda/lib/python3.10/site-packages/wandb/sdk/wandb_run.py", line 401, in wrapper_fn
    return func(self, *args, **kwargs)
  File "/opt/conda/lib/python3.10/site-packages/wandb/sdk/wandb_run.py", line 1444, in _console_raw_callback
    self._backend.interface.publish_output_raw(name, data)
  File "/opt/conda/lib/python3.10/site-packages/wandb/sdk/interface/interface.py", line 761, in publish_output_raw
    self._publish_output_raw(o)
  File "/opt/conda/lib/python3.10/site-packages/wandb/sdk/interface/interface_shared.py", line 38, in _publish_output_raw
    self._publish(rec)
  File "/opt/conda/lib/python3.10/site-packages/wandb/sdk/interface/interface_sock.py", line 39, in _publish
    self._sock_client.send_record_publish(record)
  File "/opt/conda/lib/python3.10/site-packages/wandb/sdk/lib/sock_client.py", line 174, in send_record_publish
    self.send_server_request(server_req)
  File "/opt/conda/lib/python3.10/site-packages/wandb/sdk/lib/sock_client.py", line 154, in send_server_request
    self._send_message(msg)
  File "/opt/conda/lib/python3.10/site-packages/wandb/sdk/lib/sock_client.py", line 151, in _send_message
    self._sendall_with_error_handle(header + data)
  File "/opt/conda/lib/python3.10/site-packages/wandb/sdk/lib/sock_client.py", line 130, in _sendall_with_error_handle
    sent = self._sock.send(data)
BrokenPipeError: [Errno 32] Broken pipe
2025-08-29 15:57:33,403 ERROR   MainThread:2231109 [redirect.py:_on_write():661] error in stderr callback
Traceback (most recent call last):
  File "/opt/conda/lib/python3.10/site-packages/wandb/sdk/lib/redirect.py", line 659, in _on_write
    cb(written_data)
  File "/opt/conda/lib/python3.10/site-packages/wandb/sdk/wandb_run.py", line 2302, in <lambda>
    lambda data: self._console_raw_callback("stderr", data),
  File "/opt/conda/lib/python3.10/site-packages/wandb/sdk/wandb_run.py", line 401, in wrapper_fn
    return func(self, *args, **kwargs)
  File "/opt/conda/lib/python3.10/site-packages/wandb/sdk/wandb_run.py", line 1444, in _console_raw_callback
    self._backend.interface.publish_output_raw(name, data)
  File "/opt/conda/lib/python3.10/site-packages/wandb/sdk/interface/interface.py", line 761, in publish_output_raw
    self._publish_output_raw(o)
  File "/opt/conda/lib/python3.10/site-packages/wandb/sdk/interface/interface_shared.py", line 38, in _publish_output_raw
    self._publish(rec)
  File "/opt/conda/lib/python3.10/site-packages/wandb/sdk/interface/interface_sock.py", line 39, in _publish
    self._sock_client.send_record_publish(record)
  File "/opt/conda/lib/python3.10/site-packages/wandb/sdk/lib/sock_client.py", line 174, in send_record_publish
    self.send_server_request(server_req)
  File "/opt/conda/lib/python3.10/site-packages/wandb/sdk/lib/sock_client.py", line 154, in send_server_request
    self._send_message(msg)
  File "/opt/conda/lib/python3.10/site-packages/wandb/sdk/lib/sock_client.py", line 151, in _send_message
    self._sendall_with_error_handle(header + data)
  File "/opt/conda/lib/python3.10/site-packages/wandb/sdk/lib/sock_client.py", line 130, in _sendall_with_error_handle
    sent = self._sock.send(data)
BrokenPipeError: [Errno 32] Broken pipe
2025-08-29 15:57:33,403 ERROR   MainThread:2231109 [redirect.py:_on_write():661] error in stderr callback
Traceback (most recent call last):
  File "/opt/conda/lib/python3.10/site-packages/wandb/sdk/lib/redirect.py", line 659, in _on_write
    cb(written_data)
  File "/opt/conda/lib/python3.10/site-packages/wandb/sdk/wandb_run.py", line 2302, in <lambda>
    lambda data: self._console_raw_callback("stderr", data),
  File "/opt/conda/lib/python3.10/site-packages/wandb/sdk/wandb_run.py", line 401, in wrapper_fn
    return func(self, *args, **kwargs)
  File "/opt/conda/lib/python3.10/site-packages/wandb/sdk/wandb_run.py", line 1444, in _console_raw_callback
    self._backend.interface.publish_output_raw(name, data)
  File "/opt/conda/lib/python3.10/site-packages/wandb/sdk/interface/interface.py", line 761, in publish_output_raw
    self._publish_output_raw(o)
  File "/opt/conda/lib/python3.10/site-packages/wandb/sdk/interface/interface_shared.py", line 38, in _publish_output_raw
    self._publish(rec)
  File "/opt/conda/lib/python3.10/site-packages/wandb/sdk/interface/interface_sock.py", line 39, in _publish
    self._sock_client.send_record_publish(record)
  File "/opt/conda/lib/python3.10/site-packages/wandb/sdk/lib/sock_client.py", line 174, in send_record_publish
    self.send_server_request(server_req)
  File "/opt/conda/lib/python3.10/site-packages/wandb/sdk/lib/sock_client.py", line 154, in send_server_request
    self._send_message(msg)
  File "/opt/conda/lib/python3.10/site-packages/wandb/sdk/lib/sock_client.py", line 151, in _send_message
    self._sendall_with_error_handle(header + data)
  File "/opt/conda/lib/python3.10/site-packages/wandb/sdk/lib/sock_client.py", line 130, in _sendall_with_error_handle
    sent = self._sock.send(data)
BrokenPipeError: [Errno 32] Broken pipe
2025-08-29 15:57:33,403 ERROR   MainThread:2231109 [redirect.py:_on_write():661] error in stderr callback
Traceback (most recent call last):
  File "/opt/conda/lib/python3.10/site-packages/wandb/sdk/lib/redirect.py", line 659, in _on_write
    cb(written_data)
  File "/opt/conda/lib/python3.10/site-packages/wandb/sdk/wandb_run.py", line 2302, in <lambda>
    lambda data: self._console_raw_callback("stderr", data),
  File "/opt/conda/lib/python3.10/site-packages/wandb/sdk/wandb_run.py", line 401, in wrapper_fn
    return func(self, *args, **kwargs)
  File "/opt/conda/lib/python3.10/site-packages/wandb/sdk/wandb_run.py", line 1444, in _console_raw_callback
    self._backend.interface.publish_output_raw(name, data)
  File "/opt/conda/lib/python3.10/site-packages/wandb/sdk/interface/interface.py", line 761, in publish_output_raw
    self._publish_output_raw(o)
  File "/opt/conda/lib/python3.10/site-packages/wandb/sdk/interface/interface_shared.py", line 38, in _publish_output_raw
    self._publish(rec)
  File "/opt/conda/lib/python3.10/site-packages/wandb/sdk/interface/interface_sock.py", line 39, in _publish
    self._sock_client.send_record_publish(record)
  File "/opt/conda/lib/python3.10/site-packages/wandb/sdk/lib/sock_client.py", line 174, in send_record_publish
    self.send_server_request(server_req)
  File "/opt/conda/lib/python3.10/site-packages/wandb/sdk/lib/sock_client.py", line 154, in send_server_request
    self._send_message(msg)
  File "/opt/conda/lib/python3.10/site-packages/wandb/sdk/lib/sock_client.py", line 151, in _send_message
    self._sendall_with_error_handle(header + data)
  File "/opt/conda/lib/python3.10/site-packages/wandb/sdk/lib/sock_client.py", line 130, in _sendall_with_error_handle
    sent = self._sock.send(data)
BrokenPipeError: [Errno 32] Broken pipe
2025-08-29 15:57:33,404 ERROR   MainThread:2231109 [redirect.py:_on_write():661] error in stderr callback
Traceback (most recent call last):
  File "/opt/conda/lib/python3.10/site-packages/wandb/sdk/lib/redirect.py", line 659, in _on_write
    cb(written_data)
  File "/opt/conda/lib/python3.10/site-packages/wandb/sdk/wandb_run.py", line 2302, in <lambda>
    lambda data: self._console_raw_callback("stderr", data),
  File "/opt/conda/lib/python3.10/site-packages/wandb/sdk/wandb_run.py", line 401, in wrapper_fn
    return func(self, *args, **kwargs)
  File "/opt/conda/lib/python3.10/site-packages/wandb/sdk/wandb_run.py", line 1444, in _console_raw_callback
    self._backend.interface.publish_output_raw(name, data)
  File "/opt/conda/lib/python3.10/site-packages/wandb/sdk/interface/interface.py", line 761, in publish_output_raw
    self._publish_output_raw(o)
  File "/opt/conda/lib/python3.10/site-packages/wandb/sdk/interface/interface_shared.py", line 38, in _publish_output_raw
    self._publish(rec)
  File "/opt/conda/lib/python3.10/site-packages/wandb/sdk/interface/interface_sock.py", line 39, in _publish
    self._sock_client.send_record_publish(record)
  File "/opt/conda/lib/python3.10/site-packages/wandb/sdk/lib/sock_client.py", line 174, in send_record_publish
    self.send_server_request(server_req)
  File "/opt/conda/lib/python3.10/site-packages/wandb/sdk/lib/sock_client.py", line 154, in send_server_request
    self._send_message(msg)
  File "/opt/conda/lib/python3.10/site-packages/wandb/sdk/lib/sock_client.py", line 151, in _send_message
    self._sendall_with_error_handle(header + data)
  File "/opt/conda/lib/python3.10/site-packages/wandb/sdk/lib/sock_client.py", line 130, in _sendall_with_error_handle
    sent = self._sock.send(data)
BrokenPipeError: [Errno 32] Broken pipe
2025-08-29 15:57:33,404 ERROR   MainThread:2231109 [redirect.py:_on_write():661] error in stderr callback
Traceback (most recent call last):
  File "/opt/conda/lib/python3.10/site-packages/wandb/sdk/lib/redirect.py", line 659, in _on_write
    cb(written_data)
  File "/opt/conda/lib/python3.10/site-packages/wandb/sdk/wandb_run.py", line 2302, in <lambda>
    lambda data: self._console_raw_callback("stderr", data),
  File "/opt/conda/lib/python3.10/site-packages/wandb/sdk/wandb_run.py", line 401, in wrapper_fn
    return func(self, *args, **kwargs)
  File "/opt/conda/lib/python3.10/site-packages/wandb/sdk/wandb_run.py", line 1444, in _console_raw_callback
    self._backend.interface.publish_output_raw(name, data)
  File "/opt/conda/lib/python3.10/site-packages/wandb/sdk/interface/interface.py", line 761, in publish_output_raw
    self._publish_output_raw(o)
  File "/opt/conda/lib/python3.10/site-packages/wandb/sdk/interface/interface_shared.py", line 38, in _publish_output_raw
    self._publish(rec)
  File "/opt/conda/lib/python3.10/site-packages/wandb/sdk/interface/interface_sock.py", line 39, in _publish
    self._sock_client.send_record_publish(record)
  File "/opt/conda/lib/python3.10/site-packages/wandb/sdk/lib/sock_client.py", line 174, in send_record_publish
    self.send_server_request(server_req)
  File "/opt/conda/lib/python3.10/site-packages/wandb/sdk/lib/sock_client.py", line 154, in send_server_request
    self._send_message(msg)
  File "/opt/conda/lib/python3.10/site-packages/wandb/sdk/lib/sock_client.py", line 151, in _send_message
    self._sendall_with_error_handle(header + data)
  File "/opt/conda/lib/python3.10/site-packages/wandb/sdk/lib/sock_client.py", line 130, in _sendall_with_error_handle
    sent = self._sock.send(data)
BrokenPipeError: [Errno 32] Broken pipe
2025-08-29 15:57:33,404 ERROR   MainThread:2231109 [redirect.py:_on_write():661] error in stderr callback
Traceback (most recent call last):
  File "/opt/conda/lib/python3.10/site-packages/wandb/sdk/lib/redirect.py", line 659, in _on_write
    cb(written_data)
  File "/opt/conda/lib/python3.10/site-packages/wandb/sdk/wandb_run.py", line 2302, in <lambda>
    lambda data: self._console_raw_callback("stderr", data),
  File "/opt/conda/lib/python3.10/site-packages/wandb/sdk/wandb_run.py", line 401, in wrapper_fn
    return func(self, *args, **kwargs)
  File "/opt/conda/lib/python3.10/site-packages/wandb/sdk/wandb_run.py", line 1444, in _console_raw_callback
    self._backend.interface.publish_output_raw(name, data)
  File "/opt/conda/lib/python3.10/site-packages/wandb/sdk/interface/interface.py", line 761, in publish_output_raw
    self._publish_output_raw(o)
  File "/opt/conda/lib/python3.10/site-packages/wandb/sdk/interface/interface_shared.py", line 38, in _publish_output_raw
    self._publish(rec)
  File "/opt/conda/lib/python3.10/site-packages/wandb/sdk/interface/interface_sock.py", line 39, in _publish
    self._sock_client.send_record_publish(record)
  File "/opt/conda/lib/python3.10/site-packages/wandb/sdk/lib/sock_client.py", line 174, in send_record_publish
    self.send_server_request(server_req)
  File "/opt/conda/lib/python3.10/site-packages/wandb/sdk/lib/sock_client.py", line 154, in send_server_request
    self._send_message(msg)
  File "/opt/conda/lib/python3.10/site-packages/wandb/sdk/lib/sock_client.py", line 151, in _send_message
    self._sendall_with_error_handle(header + data)
  File "/opt/conda/lib/python3.10/site-packages/wandb/sdk/lib/sock_client.py", line 130, in _sendall_with_error_handle
    sent = self._sock.send(data)
BrokenPipeError: [Errno 32] Broken pipe
2025-08-29 15:57:33,405 ERROR   MainThread:2231109 [redirect.py:_on_write():661] error in stderr callback
Traceback (most recent call last):
  File "/opt/conda/lib/python3.10/site-packages/wandb/sdk/lib/redirect.py", line 659, in _on_write
    cb(written_data)
  File "/opt/conda/lib/python3.10/site-packages/wandb/sdk/wandb_run.py", line 2302, in <lambda>
    lambda data: self._console_raw_callback("stderr", data),
  File "/opt/conda/lib/python3.10/site-packages/wandb/sdk/wandb_run.py", line 401, in wrapper_fn
    return func(self, *args, **kwargs)
  File "/opt/conda/lib/python3.10/site-packages/wandb/sdk/wandb_run.py", line 1444, in _console_raw_callback
    self._backend.interface.publish_output_raw(name, data)
  File "/opt/conda/lib/python3.10/site-packages/wandb/sdk/interface/interface.py", line 761, in publish_output_raw
    self._publish_output_raw(o)
  File "/opt/conda/lib/python3.10/site-packages/wandb/sdk/interface/interface_shared.py", line 38, in _publish_output_raw
    self._publish(rec)
  File "/opt/conda/lib/python3.10/site-packages/wandb/sdk/interface/interface_sock.py", line 39, in _publish
    self._sock_client.send_record_publish(record)
  File "/opt/conda/lib/python3.10/site-packages/wandb/sdk/lib/sock_client.py", line 174, in send_record_publish
    self.send_server_request(server_req)
  File "/opt/conda/lib/python3.10/site-packages/wandb/sdk/lib/sock_client.py", line 154, in send_server_request
    self._send_message(msg)
  File "/opt/conda/lib/python3.10/site-packages/wandb/sdk/lib/sock_client.py", line 151, in _send_message
    self._sendall_with_error_handle(header + data)
  File "/opt/conda/lib/python3.10/site-packages/wandb/sdk/lib/sock_client.py", line 130, in _sendall_with_error_handle
    sent = self._sock.send(data)
BrokenPipeError: [Errno 32] Broken pipe
